Workbook

Sheet INFO
A1: Lote | B1: Pesado el | C1: Llegada el | D1: desembarcado | E1: cantidad | F1: pesados | G1: Total pesados (kg) | H1: Peso promedio (kg) | I1: Cliente planta | J1: Granja
A2: 250627-6566 | B2: 2025-06-27 18:26:16 | C2: 2025-06-27 17:12:56 | D2: 2025-06-27 18:24:16 | E2: 40 | F2: 40 | G2: 4574 | H2: 114.35 | I2: IVAN ECHEVERRI PALACIO | J2: INVERSIONES SOGA SA
A9: Lote | B9: Beneficiados | C9: Beneficiado el | D9: RCC (%) | E9: RCR (%) | F9: PCC (kg) | G9: PCR (kg) | H9: ML (m.m) | I9: MC (kg) | J9: GD (m.m) | K9: Cliente planta | L9: Cliente factura
A10: 250627-6566 | B10: 40 | C10: 2025-06-28 00:46:43 | D10: 83.47 | E10: 80.1 | F10: 95.29 | G10: 91.6 | H10: 72.56 | I10: 52.92 | J10: 15.75 | K10: IVAN ECHEVERRI PALACIO | L10: INVERSIONES SOGA SA | M10: LA CIRCASIA
A17: Lote | B17: Despacho inicio | C17: Despacho final | D17: Total de canales (cargadas) | E17: Total de visceras (cargadas) | F17: Destino
A18: 250627-6566 | B18: 0 | C18: 0 | D18: 7 | E18: 0 | F18: 0 | G18: 0 | H18: PACARDYL SUPERMERCADO -MAYORISTA | I18: IVAN ECHEVERRI PALACIO | J18: INVERSIONES SOGA SA
A19: 250627-6566 | B19: 0 | C19: 0 | D19: 3 | E19: 0 | F19: 0 | G19: 0 | H19: CARNES VITAL SAS | I19: IVAN ECHEVERRI PALACIO | J19: INVERSIONES SOGA SA
A20: 250627-6566 | B20: 0 | C20: 0 | D20: 20 | E20: 0 | F20: 0 | G20: 0 | H20: CARNES JP (PEDRO MONTOYA) | I20: IVAN ECHEVERRI PALACIO | J20: INVERSIONES SOGA SA
A21: 250627-6566 | B21: 0 | C21: 0 | D21: 8 | E21: 0 | F21: 0 | G21: 0 | H21: CARNES JP (PEDRO MONTOYA) | I21: IVAN ECHEVERRI PALACIO | J21: INVERSIONES SOGA SA
A22: 250627-6566 | B22: 0 | C22: 0 | D22: 2 | E22: 0 | F22: 0 | G22: 0 | H22: CARNES COSTA AZUL | I22: IVAN ECHEVERRI PALACIO | J22: INVERSIONES SOGA SA

Sheet despacho
B1: Fecha fin cargue | C1: CC | D1: FHPCC | E1: Granja | F1: PPE (kg) | G1: PCC (kg) | H1: FHPCR | I1: PCR (kg) | J1: GD (mm) | K1: ML (mm) | L1: SEUROP | M1: MC % | N1: MC (Kg) | O1: PSE | P1: Destino | Q1: Vehículo | R1: Código Despacho | S1: Merma PCC(Kg) | T1: Merma PCC(%) | U1: Merma PEC(Kg) | V1: Merma PEC(%) | W1: Merma PCR(PCC Kg) | X1: Merma PCR(PCC %) | Y1: Merma PCR(PEC Kg) | Z1: Merma PCR(PEC %)
A2: 2025-07-03 03:26:20 | B2: 2025-07-03 03:34:36 | C2: 6566-1 | E2: LA CIRCASIA | F2: 127.92 | G2: 106.6 | I2: 102.1 | J2: 12 | K2: 86.4 | L2: S | M2: 59.84 | N2: 63.79 | O2: 56 | P2: PACARDYL SUPERMERCADO -MAYORISTA | Q2: WCP689 | R2: DE-7845
A3: 2025-07-03 03:26:20 | B3: 2025-07-03 03:34:36 | C3: 6566-2 | E3: LA CIRCASIA | F3: 119.88 | G3: 99.9 | I3: 95.7 | J3: 18 | K3: 75.2 | L3: E | M3: 54.29 | N3: 54.24 | O3: 52 | P3: PACARDYL SUPERMERCADO -MAYORISTA | Q3: WCP689 | R3: DE-7845
A4: 2025-07-03 03:26:20 | B4: 2025-07-03 03:34:36 | C4: 6566-3 | E4: LA CIRCASIA | F4: 109.08 | G4: 90.9 | I4: 86.8 | J4: 15.6 | K4: 83.6 | L4: E | M4: 57.04 | N4: 51.85 | O4: 51 | P4: PACARDYL SUPERMERCADO -MAYORISTA | Q4: WCP689 | R4: DE-7845
A5: 2025-07-03 03:26:20 | B5: 2025-07-03 03:34:36 | C5: 6566-4 | E5: LA CIRCASIA | F5: 117.12 | G5: 97.6 | I5: 93.8 | J5: 15.6 | K5: 75.6 | L5: E | M5: 55.96 | N5: 54.62 | O5: 51 | P5: PACARDYL SUPERMERCADO -MAYORISTA | Q5: WCP689 | R5: DE-7845
A6: 2025-07-03 03:26:20 | B6: 2025-07-03 03:34:36 | C6: 6566-5 | E6: LA CIRCASIA | F6: 117.84 | G6: 98.2 | I6: 94.5 | J6: 18.4 | K6: 73.6 | L6: E | M6: 53.8 | N6: 52.84 | O6: 47 | P6: PACARDYL SUPERMERCADO -MAYORISTA | Q6: WCP689 | R6: DE-7845
A7: 2025-07-03 03:26:20 | B7: 2025-07-03 03:34:36 | C7: 6566-6 | E7: LA CIRCASIA | F7: 123.6 | G7: 103 | I7: 98.3 | J7: 15.2 | K7: 74 | L7: E | M7: 56.02 | N7: 57.7 | O7: 44 | P7: PACARDYL SUPERMERCADO -MAYORISTA | Q7: WCP689 | R7: DE-7845
A8: 2025-07-01 03:36:52 | B8: 2025-07-01 03:51:05 | C8: 6566-7 | E8: LA CIRCASIA | F8: 117 | G8: 97.5 | I8: 93.6 | J8: 12.4 | K8: 70.8 | L8: E | M8: 57.47 | N8: 56.03 | O8: 47 | P8: CARNES VITAL SAS | Q8: WGU858 | R8: DE-7788
A9: 2025-07-01 03:36:52 | B9: 2025-07-01 03:51:05 | C9: 6566-8 | E9: LA CIRCASIA | F9: 115.44 | G9: 96.2 | I9: 92.9 | J9: 16.8 | K9: 76.8 | L9: E | M9: 55.31 | N9: 53.21 | O9: 52 | P9: CARNES VITAL SAS | Q9: WGU858 | R9: DE-7788
A10: 2025-07-01 03:36:52 | B10: 2025-07-01 03:51:05 | C10: 6566-9 | E10: LA CIRCASIA | F10: 118.2 | G10: 98.5 | I10: 95 | J10: 14 | K10: 74.4 | L10: E | M10: 56.88 | N10: 56.02 | O10: 48 | P10: CARNES VITAL SAS | Q10: WGU858 | R10: DE-7788
A11: 2025-07-03 03:26:20 | B11: 2025-07-03 03:34:36 | C11: 6566-10 | E11: LA CIRCASIA | F11: 116.4 | G11: 97 | I11: 93.2 | J11: 19.2 | K11: 77.6 | L11: E | M11: 53.81 | N11: 52.19 | O11: 43 | P11: PACARDYL SUPERMERCADO -MAYORISTA | Q11: WCP689 | R11: DE-7845
A12: 2025-07-03 03:26:20 | B12: 2025-07-03 03:34:36 | C12: 6566-11 | E12: LA CIRCASIA | F12: 126.48 | G12: 105.4 | I12: 101.3 | J12: 19.2 | K12: 66.4 | L12: U | M12: 52.29 | N12: 55.12 | O12: 39 | P12: CARNES COSTA AZUL | Q12: WCP689 | R12: DE-7845
A13: 2025-07-03 03:26:20 | B13: 2025-07-03 03:34:36 | C13: 6566-12 | E13: LA CIRCASIA | F13: 114.12 | G13: 95.1 | I13: 91.3 | J13: 20.8 | K13: 71.2 | L13: U | M13: 51.86 | N13: 49.32 | O13: 45 | P13: CARNES COSTA AZUL | Q13: WCP689 | R13: DE-7845
... A34: 2025-07-03 06:49:14 | B34: 2025-07-03 06:56:48 | C34: 6566-33 | E34: LA CIRCASIA | F34: 106.32 | G34: 88.6 | I34: 85.3 | J34: 8 | K34: 70 | L34: S | M34: 60.33 | N34: 53.45 | O34: 46 | P34: CARNES JP (PEDRO MONTOYA) | Q34: XGC579 | R34: DE-7845
A35: 2025-07-03 06:49:14 | B35: 2025-07-03 06:56:48 | C35: 6566-34 | E35: LA CIRCASIA | F35: 106.92 | G35: 89.1 | I35: 90.3 | P35: CARNES JP (PEDRO MONTOYA) | Q35: XGC579 | R35: DE-7845
A36: 2025-07-03 06:49:14 | B36: 2025-07-03 06:56:48 | C36: 6566-35 | E36: LA CIRCASIA | F36: 116.76 | G36: 97.3 | I36: 93.3 | J36: 20.4 | K36: 75.2 | L36: U | M36: 52.67 | N36: 51.25 | O36: 49 | P36: CARNES JP (PEDRO MONTOYA) | Q36: XGC579 | R36: DE-7845
A37: 2025-07-03 06:49:14 | B37: 2025-07-03 06:56:48 | C37: 6566-36 | E37: LA CIRCASIA | F37: 110.76 | G37: 92.3 | I37: 89.1 | J37: 19.6 | K37: 68.8 | L37: U | M37: 52.35 | N37: 48.32 | O37: 44 | P37: CARNES JP (PEDRO MONTOYA) | Q37: XGC579 | R37: DE-7845
A38: 2025-07-03 06:49:14 | B38: 2025-07-03 06:56:48 | C38: 6566-37 | E38: LA CIRCASIA | F38: 97.32 | G38: 81.1 | I38: 77.9 | J38: 14.4 | K38: 71.6 | L38: E | M38: 56.23 | N38: 45.6 | O38: 43 | P38: CARNES JP (PEDRO MONTOYA) | Q38: XGC579 | R38: DE-7845
A39: 2025-07-03 06:49:14 | B39: 2025-07-03 06:56:48 | C39: 6566-38 | E39: LA CIRCASIA | F39: 111.48 | G39: 92.9 | I39: 89.2 | J39: 16.4 | K39: 72.8 | L39: E | M39: 55.04 | N39: 51.14 | O39: 48 | P39: CARNES JP (PEDRO MONTOYA) | Q39: XGC579 | R39: DE-7845
A40: 2025-07-03 06:49:14 | B40: 2025-07-03 06:56:48 | C40: 6566-39 | E40: LA CIRCASIA | F40: 110.4 | G40: 92 | I40: 88 | J40: 11.2 | K40: 72.4 | L40: S | M40: 58.5 | N40: 53.82 | O40: 41 | P40: CARNES JP (PEDRO MONTOYA) | Q40: XGC579 | R40: DE-7845
A41: 2025-07-03 06:49:14 | B41: 2025-07-03 06:56:48 | C41: 6566-40 | E41: LA CIRCASIA | F41: 115.8 | G41: 96.5 | I41: 93 | J41: 17.2 | K41: 75.6 | L41: E | M41: 54.88 | N41: 52.96 | O41: 43 | P41: CARNES JP (PEDRO MONTOYA) | Q41: XGC579 | R41: DE-7845

Sheet lIQUIDACION
A1: LIQUIDACION PAGO POR CALIDAD LOTES DE CERDO | W1: CRITERIOS PESO
W2: COLAS
K3: Planta: | L3: CG | N3: Codigo | O3: 6566 | P3: Proveedor: | Q3: =+INFO!L10 | W3: vivo | X3: vivo
B4: Peso | H4: % | I4: mm | K4: Fecha llegada | L4: 45835.717 | M4: =+INFO!C2 | P4: Granja: | Q4: =+despacho!E2 | W4: <79,99 | X4: >0
A5: # | B5: KILOS | E5: <90 | F5: menor | G5: grasa | H5: magro | I5: Lomo | K5: fecha pesaje | L5: 45835.768 | M5: =+INFO!B2 | N5: =+M5-M4
A6: Canal | B6: vivo | C6: caliente | D6: RFG | E6: >80 | F6: 80 | G6: dorsal | K6: Fecha sacrificio | L6: 45836.032 | M6: =+INFO!C10 | N6: =+(M6-M5) | P6: Comprador: | Q6: =+despacho!P2 | W6: LIVIANOS
A7: =+despacho!C2 | B7: =+IF((C7/$N$15)>0,(C7/$N$15)," ") | C7: =+despacho!G2 | D7: =+despacho!I2 | E7: =IF(AND(B7<$M$24,B7>$M$25),1,0) | F7: =IF(AND(B7<$M$25,B7>0),1,0) | G7: =+despacho!J2 | H7: =+despacho!M2 | I7: =+despacho!K2 | J7: =+despacho!L2 | K7: Fecha despacho | M7: =+INFO!B18 | P7: Facturar a: | Q7: =+VLOOKUP($Q$6,facturar!$A$2:$E$94,2,0) | V7: =+C7-D7 | W7: vivo | X7: vivo
A8: =+despacho!C3 | B8: =+IF((C8/$N$15)>0,(C8/$N$15)," ") | C8: =+despacho!G3 | D8: =+despacho!I3 | E8: =IF(AND(B8<$M$24,B8>$M$25),1,0) | F8: =IF(AND(B8<$M$25,B8>0),1,0) | G8: =+despacho!J3 | H8: =+despacho!M3 | I8: =+despacho!K3 | J8: =+despacho!L3 | M8: =+INFO!C18 | N8: =+M8-M7 | P8: NIT: | Q8: =+VLOOKUP($Q$6,facturar!$A$2:$E$94,3,0) | V8: =+C8-D8 | W8: >=80,0 | X8: <=89,99
A9: =+despacho!C4 | B9: =+IF((C9/$N$15)>0,(C9/$N$15)," ") | C9: =+despacho!G4 | D9: =+despacho!I4 | E9: =IF(AND(B9<$M$24,B9>$M$25),1,0) | F9: =IF(AND(B9<$M$25,B9>0),1,0) | G9: =+despacho!J4 | H9: =+despacho!M4 | I9: =+despacho!K4 | J9: =+despacho!L4 | M9: despacho | N9: lote | P9: Dirección: | Q9: =+VLOOKUP($Q$6,facturar!$A$2:$E$94,4,0) | V9: =+C9-D9
A10: =+despacho!C5 | B10: =+IF((C10/$N$15)>0,(C10/$N$15)," ") | C10: =+despacho!G5 | D10: =+despacho!I5 | E10: =IF(AND(B10<$M$24,B10>$M$25),1,0) | F10: =IF(AND(B10<$M$25,B10>0),1,0) | G10: =+despacho!J5 | H10: =+despacho!M5 | I10: =+despacho!K5 | J10: =+despacho!L5 | L10: No cerdos: | M10: =+A79 | N10: =+INFO!E2 | P10: Teléfono: | Q10: =+VLOOKUP($Q$6,facturar!$A$2:$E$94,5,0) | V10: =+C10-D10 | W10: ESTANDAR
A11: =+despacho!C6 | B11: =+IF((C11/$N$15)>0,(C11/$N$15)," ") | C11: =+despacho!G6 | D11: =+despacho!I6 | E11: =IF(AND(B11<$M$24,B11>$M$25),1,0) | F11: =IF(AND(B11<$M$25,B11>0),1,0) | G11: =+despacho!J6 | H11: =+despacho!M6 | I11: =+despacho!K6 | J11: =+despacho!L6 | V11: =+C11-D11 | W11: vivo | X11: vivo
A12: =+despacho!C7 | B12: =+IF((C12/$N$15)>0,(C12/$N$15)," ") | C12: =+despacho!G7 | D12: =+despacho!I7 | E12: =IF(AND(B12<$M$24,B12>$M$25),1,0) | F12: =IF(AND(B12<$M$25,B12>0),1,0) | G12: =+despacho!J7 | H12: =+despacho!M7 | I12: =+despacho!K7 | J12: =+despacho!L7 | L12: Peso vivo | N12: Canal | R12: Grasa | S12: Magro | T12: Lomo | V12: =+C12-D12 | W12: >=89,99 | X12: <180
A13: =+despacho!C8 | B13: =+IF((C13/$N$15)>0,(C13/$N$15)," ") | C13: =+despacho!G8 | D13: =+despacho!I8 | E13: =IF(AND(B13<$M$24,B13>$M$25),1,0) | F13: =IF(AND(B13<$M$25,B13>0),1,0) | G13: =+despacho!J8 | H13: =+despacho!M8 | I13: =+despacho!K8 | J13: =+despacho!L8 | L13: Lote | M13: Prom | N13: caliente | O13: RFG | P13: merma | Q13: Kg/cerdo | R13: mm | S13: % | T13: mm | V13: =+C13-D13
A14: =+despacho!C9 | B14: =+IF((C14/$N$15)>0,(C14/$N$15)," ") | C14: =+despacho!G9 | D14: =+despacho!I9 | E14: =IF(AND(B14<$M$24,B14>$M$25),1,0) | F14: =IF(AND(B14<$M$25,B14>0),1,0) | G14: =+despacho!J9 | H14: =+despacho!M9 | I14: =+despacho!K9 | J14: =+despacho!L9 | K14: lote | L14: =+INFO!G2 | M14: =+L14/N10 | N14: =+INFO!F10*INFO!B10 | O14: =+INFO!G10*INFO!B10 | P14: =+(N14-O14)/N14 | Q14: =+(N14-O14)/N10 | R14: =+INFO!J10 | S14: =+INFO!I10 | T14: =+INFO!H10 | V14: =+C14-D14
A15: =+despacho!C10 | B15: =+IF((C15/$N$15)>0,(C15/$N$15)," ") | C15: =+despacho!G10 | D15: =+despacho!I10 | E15: =IF(AND(B15<$M$24,B15>$M$25),1,0) | F15: =IF(AND(B15<$M$25,B15>0),1,0) | G15: =+despacho!J10 | H15: =+despacho!M10 | I15: =+despacho!K10 | J15: =+despacho!L10 | N15: =+INFO!D10/100 | O15: =+O14/L14 | V15: =+C15-D15 | W15: CRITERIOS GRASA
A16: =+despacho!C11 | B16: =+IF((C16/$N$15)>0,(C16/$N$15)," ") | C16: =+despacho!G11 | D16: =+despacho!I11 | E16: =IF(AND(B16<$M$24,B16>$M$25),1,0) | F16: =IF(AND(B16<$M$25,B16>0),1,0) | G16: =+despacho!J11 | H16: =+despacho!M11 | I16: =+despacho!K11 | J16: =+despacho!L11 | K16: entrega | L16: =+B79 | M16: =+L16/M10 | N16: =+C79 | O16: =+D79 | P16: =+(N16-O16)/N16 | Q16: =+(N16-O16)/M10 | R16: =+G79/M10 | S16: =+H79/M10 | T16: =+I79/M10 | V16: =+C16-D16
A17: =+despacho!C12 | B17: =+IF((C17/$N$15)>0,(C17/$N$15)," ") | C17: =+despacho!G12 | D17: =+despacho!I12 | E17: =IF(AND(B17<$M$24,B17>$M$25),1,0) | F17: =IF(AND(B17<$M$25,B17>0),1,0) | G17: =+despacho!J12 | H17: =+despacho!M12 | I17: =+despacho!K12 | J17: =+despacho!L12 | N17: =+N16/L16 | O17: =+O16/L16 | V17: =+C17-D17 | W17: TOCINUDO 1
A18: =+despacho!C13 | B18: =+IF((C18/$N$15)>0,(C18/$N$15)," ") | C18: =+despacho!G13 | D18: =+despacho!I13 | E18: =IF(AND(B18<$M$24,B18>$M$25),1,0) | F18: =IF(AND(B18<$M$25,B18>0),1,0) | G18: =+despacho!J13 | H18: =+despacho!M13 | I18: =+despacho!K13 | J18: =+despacho!L13 | N18: =+O46 | O18: =+O47 | R18: H | U18: =+P48/(S14/100*N14) | V18: =+C18-D18 | W18: dorsal | X18: dorsal | Y18: vivo
A19: =+despacho!C14 | B19: =+IF((C19/$N$15)>0,(C19/$N$15)," ") | C19: =+despacho!G14 | D19: =+despacho!I14 | E19: =IF(AND(B19<$M$24,B19>$M$25),1,0) | F19: =IF(AND(B19<$M$25,B19>0),1,0) | G19: =+despacho!J14 | H19: =+despacho!M14 | I19: =+despacho!K14 | J19: =+despacho!L14 | R19: MIC | V19: =+C19-D19 | W19: <22 | X19: >=18 | Y19: <=180
A20: =+despacho!C15 | B20: =+IF((C20/$N$15)>0,(C20/$N$15)," ") | C20: =+despacho!G15 | D20: =+despacho!I15 | E20: =IF(AND(B20<$M$24,B20>$M$25),1,0) | F20: =IF(AND(B20<$M$25,B20>0),1,0) | G20: =+despacho!J15 | H20: =+despacho!M15 | I20: =+despacho!K15 | J20: =+despacho!L15 | K20: RENDIMIENTO | L20: Rango de Control | P20: % | Q20: castigo o | S20: Tole- | T20: $/Kg | U20: Valor cerdos | V20: =+C20-D20
A21: =+despacho!C16 | B21: =+IF((C21/$N$15)>0,(C21/$N$15)," ") | C21: =+despacho!G16 | D21: =+despacho!I16 | E21: =IF(AND(B21<$M$24,B21>$M$25),1,0) | F21: =IF(AND(B21<$M$25,B21>0),1,0) | G21: =+despacho!J16 | H21: =+despacho!M16 | I21: =+despacho!K16 | J21: =+despacho!L16 | K21: LOTE | L21: mínimo | M21: máximo | N21: KGS | O21: # CERDOS | P21: Kgs | Q21: bonificacion/kg | S21: rancia | U21: /categoria | V21: =+C21-D21 | W21: TOCINUDO 2
A22: =+despacho!C17 | B22: =+IF((C22/$N$15)>0,(C22/$N$15)," ") | C22: =+despacho!G17 | D22: =+despacho!I17 | E22: =IF(AND(B22<$M$24,B22>$M$25),1,0) | F22: =IF(AND(B22<$M$25,B22>0),1,0) | G22: =+despacho!J17 | H22: =+despacho!M17 | I22: =+despacho!K17 | J22: =+despacho!L17 | L22: 0.83 | M22: 0.835 | Q22: 80 | R22: /1% | T22: =+IF(N15>M22,Q22*(N15-M22)*100,IF(N15<L22,Q22*(N15-L22)*100)) | U22: =+T22*L16 | V22: =+C22-D22 | W22: dorsal | X22: vivo
A23: =+despacho!C18 | B23: =+IF((C23/$N$15)>0,(C23/$N$15)," ") | C23: =+despacho!G18 | D23: =+despacho!I18 | E23: =IF(AND(B23<$M$24,B23>$M$25),1,0) | F23: =IF(AND(B23<$M$25,B23>0),1,0) | G23: =+despacho!J18 | H23: =+despacho!M18 | I23: =+despacho!K18 | J23: =+despacho!L18 | K23: Estandar | L23: 90 | M23: 140 | N23: =DSUM($B$6:$G$78,1,W11:X12) | O23: =DCOUNT($B$6:$G$78,1,W11:X12) | P23: =+N23/$N$26 | Q23: 0 | T23: =+M35 | U23: 0 | V23: =+C23-D23 | W23: >=22 | X23: >90 | AB23: 10800
A24: =+despacho!C19 | B24: =+IF((C24/$N$15)>0,(C24/$N$15)," ") | C24: =+despacho!G19 | D24: =+despacho!I19 | E24: =IF(AND(B24<$M$24,B24>$M$25),1,0) | F24: =IF(AND(B24<$M$25,B24>0),1,0) | G24: =+despacho!J19 | H24: =+despacho!M19 | I24: =+despacho!K19 | J24: =+despacho!L19 | K24: Livianos | L24: 80 | M24: 89.99 | N24: =DSUM($B$6:$G$78,1,W7:X8) | O24: =DCOUNT($B$6:$G$78,1,W7:X8) | P24: =+N24/$N$26 | Q24: 0.1 | S24: 0.1 | T24: =+M35*(1-Q24) | U24: =+IF(O24>N10*S24,N24*(-$M$35+T24),T24*0) | V24: =+C24-D24
A25: =+despacho!C20 | B25: =+IF((C25/$N$15)>0,(C25/$N$15)," ") | C25: =+despacho!G20 | D25: =+despacho!I20 | E25: =IF(AND(B25<$M$24,B25>$M$25),1,0) | F25: =IF(AND(B25<$M$25,B25>0),1,0) | G25: =+despacho!J20 | H25: =+despacho!M20 | I25: =+despacho!K20 | J25: =+despacho!L20 | K25: Colas | L25: < | M25: 79.99 | N25: =DSUM($B$6:$G$78,1,W3:X4) | O25: =DCOUNT($B$6:$G$78,1,W3:X4) | P25: =+N25/$N$26 | Q25: 0.25 | S25: 0 | T25: =+M35*(1-Q25) | U25: =+IF(O25>N11*S25,N25*(-$M$35+T25),T25*0) | V25: =+C25-D25 | W25: ESTANDAR | AB25: =+N15*AB23/84
A26: =+despacho!C21 | B26: =+IF((C26/$N$15)>0,(C26/$N$15)," ") | C26: =+despacho!G21 | D26: =+despacho!I21 | E26: =IF(AND(B26<$M$24,B26>$M$25),1,0) | F26: =IF(AND(B26<$M$25,B26>0),1,0) | G26: =+despacho!J21 | H26: =+despacho!M21 | I26: =+despacho!K21 | J26: =+despacho!L21 | K26: Total lote | N26: =SUM(N23:N25) | O26: =SUM(O23:O25) | P26: =+N26/$N$26 | U26: =SUM(U23:U25) | V26: =+C26-D26 | W26: dorsal | X26: vivo
A27: =+despacho!C22 | B27: =+IF((C27/$N$15)>0,(C27/$N$15)," ") | C27: =+despacho!G22 | D27: =+despacho!I22 | E27: =IF(AND(B27<$M$24,B27>$M$25),1,0) | F27: =IF(AND(B27<$M$25,B27>0),1,0) | G27: =+despacho!J22 | H27: =+despacho!M22 | I27: =+despacho!K22 | J27: =+despacho!L22 | K27: Excelente: >=105 kg y | L27: <= | M27: 18 | N27: =DSUM($B$6:$G$78,1,W30:Y31) | O27: =DCOUNT($B$6:$G$78,1,W30:Y31) | P27: =+N27/$N$32 | Q27: 0.04 | T27: =+M35*(1+Q27) | U27: =+(-M35+T27)*N27 | V27: =+C27-D27 | W27: <18 | X27: <=105
A28: =+despacho!C23 | B28: =+IF((C28/$N$15)>0,(C28/$N$15)," ") | C28: =+despacho!G23 | D28: =+despacho!I23 | E28: =IF(AND(B28<$M$24,B28>$M$25),1,0) | F28: =IF(AND(B28<$M$25,B28>0),1,0) | G28: =+despacho!J23 | H28: =+despacho!M23 | I28: =+despacho!K23 | J28: =+despacho!L23 | K28: Buenos: >=115 kg | M28: >=18 <20 | N28: =DSUM($B$6:$G$78,1,W34:Y35) | O28: =DCOUNT($B$6:$G$78,1,W34:Y35) | P28: =+N28/$N$32 | Q28: 0 | T28: =+M35 | U28: =+IF(O28>$N$10*S28,N28*(-$M$35+T28),T28*0) | V28: =+C28-D28
A29: =+despacho!C24 | B29: =+IF((C29/$N$15)>0,(C29/$N$15)," ") | C29: =+despacho!G24 | D29: =+despacho!I24 | E29: =IF(AND(B29<$M$24,B29>$M$25),1,0) | F29: =IF(AND(B29<$M$25,B29>0),1,0) | G29: =+despacho!J24 | H29: =+despacho!M24 | I29: =+despacho!K24 | J29: =+despacho!L24 | K29: Estandar: <=105 Kg | L29: < | M29: 18 | N29: =DSUM($B$6:$G$78,1,W26:X27) | O29: =DCOUNT($B$6:$G$78,1,W26:X27) | P29: =+N29/$N$32 | Q29: 0 | T29: =+M35 | U29: =+IF(O29>$N$10*S29,N29*(-$M$35+T29),T29*0) | V29: =+C29-D29 | W29: EXCELENTE
A30: =+despacho!C25 | B30: =+IF((C30/$N$15)>0,(C30/$N$15)," ") | C30: =+despacho!G25 | D30: =+despacho!I25 | E30: =IF(AND(B30<$M$24,B30>$M$25),1,0) | F30: =IF(AND(B30<$M$25,B30>0),1,0) | G30: =+despacho!J25 | H30: =+despacho!M25 | I30: =+despacho!K25 | J30: =+despacho!L25 | K30: Tocinudos: kg <= 140 y mm | M30: >=18 <22 | N30: =DSUM($B$6:$G$78,1,W18:Y19)-DSUM($B$6:$G$78,1,W34:Y35) | O30: =DCOUNT($B$6:$G$78,1,W18:Y19)-DCOUNT($B$6:$G$78,1,W34:Y35) | P30: =+N30/$N$32 | Q30: 0.1 | S30: 0 | T30: =+M35*(1-Q30) | U30: =+IF(O30>$N$10*S30,N30*(-$M$35+T30),T30*0) | V30: =+C30-D30 | W30: dorsal | X30: dorsal | Y30: vivo
A31: =+despacho!C26 | B31: =+IF((C31/$N$15)>0,(C31/$N$15)," ") | C31: =+despacho!G26 | D31: =+despacho!I26 | E31: =IF(AND(B31<$M$24,B31>$M$25),1,0) | F31: =IF(AND(B31<$M$25,B31>0),1,0) | G31: =+despacho!J26 | H31: =+despacho!M26 | I31: =+despacho!K26 | J31: =+despacho!L26 | K31: kg > 90 y mm | M31: >=22 | N31: =DSUM($B$6:$G$78,1,W22:X23) | O31: =DCOUNT($B$6:$G$78,1,W22:X23) | P31: =+N31/$N$32 | Q31: 0.12 | S31: 0 | T31: =+M35*(1-Q31) | U31: =+IF(O31>$N$10*S31,N31*(-$M$35+T31),T31*0) | V31: =+C31-D31 | X31: <18 | Y31: >=105 | AC31: 8
A32: =+despacho!C27 | B32: =+IF((C32/$N$15)>0,(C32/$N$15)," ") | C32: =+despacho!G27 | D32: =+despacho!I27 | E32: =IF(AND(B32<$M$24,B32>$M$25),1,0) | F32: =IF(AND(B32<$M$25,B32>0),1,0) | G32: =+despacho!J27 | H32: =+despacho!M27 | I32: =+despacho!K27 | J32: =+despacho!L27 | K32: Total lote | N32: =SUM(N27:N31) | O32: =SUM(O27:O31) | P32: =+N32/$N$26 | U32: =SUM(U27:U31) | V32: =+C32-D32
A33: =+despacho!C28 | B33: =+IF((C33/$N$15)>0,(C33/$N$15)," ") | C33: =+despacho!G28 | D33: =+despacho!I28 | E33: =IF(AND(B33<$M$24,B33>$M$25),1,0) | F33: =IF(AND(B33<$M$25,B33>0),1,0) | G33: =+despacho!J28 | H33: =+despacho!M28 | I33: =+despacho!K28 | J33: =+despacho!L28 | U33: =+U32+U26+U22 | V33: =+C33-D33 | W33: BUENOS
A34: =+despacho!C29 | B34: =+IF((C34/$N$15)>0,(C34/$N$15)," ") | C34: =+despacho!G29 | D34: =+despacho!I29 | E34: =IF(AND(B34<$M$24,B34>$M$25),1,0) | F34: =IF(AND(B34<$M$25,B34>0),1,0) | G34: =+despacho!J29 | H34: =+despacho!M29 | I34: =+despacho!K29 | J34: =+despacho!L29 | M34: $/kg vivo | N34: $/cerdo | O34: $/lote | Q34: CLASIFICACION CANAL | V34: =+C34-D34 | W34: dorsal | X34: dorsal | Y34: vivo
A35: =+despacho!C30 | B35: =+IF((C35/$N$15)>0,(C35/$N$15)," ") | C35: =+despacho!G30 | D35: =+despacho!I30 | E35: =IF(AND(B35<$M$24,B35>$M$25),1,0) | F35: =IF(AND(B35<$M$25,B35>0),1,0) | G35: =+despacho!J30 | H35: =+despacho!M30 | I35: =+despacho!K30 | J35: =+despacho!L30 | K35: Precio base: | M35: 8100 | N35: =+O35/M10 | O35: =+M35*L16 | Q35: S | R35: =+S35/$M$10 | S35: =+COUNTIF($J$7:$J$47,"S") | T35: Mas de 60% Magro | V35: =+C35-D35 | W35: >=18 | X35: <20 | Y35: >=115
A36: =+despacho!C31 | B36: =+IF((C36/$N$15)>0,(C36/$N$15)," ") | C36: =+despacho!G31 | D36: =+despacho!I31 | E36: =IF(AND(B36<$M$24,B36>$M$25),1,0) | F36: =IF(AND(B36<$M$25,B36>0),1,0) | G36: =+despacho!J31 | H36: =+despacho!M31 | I36: =+despacho!K31 | J36: =+despacho!L31 | K36: Precio a pagar: | M36: =+O36/L16 | N36: =+O36/M10 | O36: =+O35+U33 | Q36: E | R36: =+S36/$M$10 | S36: =+COUNTIF($J$7:$J$47,"E") | T36: Entre 55% - 59% | V36: =+C36-D36
A37: =+despacho!C32 | B37: =+IF((C37/$N$15)>0,(C37/$N$15)," ") | C37: =+despacho!G32 | D37: =+despacho!I32 | E37: =IF(AND(B37<$M$24,B37>$M$25),1,0) | F37: =IF(AND(B37<$M$25,B37>0),1,0) | G37: =+despacho!J32 | H37: =+despacho!M32 | I37: =+despacho!K32 | J37: =+despacho!L32 | K37: Precio pagado: | M37: =+M36 | N37: =+M37*M14 | O37: =+M37*L16 | Q37: U | R37: =+S37/$M$10 | S37: =+COUNTIF($J$7:$J$47,"U") | T37: Entre 50% - 54% | V37: =+C37-D37
A38: =+despacho!C33 | B38: =+IF((C38/$N$15)>0,(C38/$N$15)," ") | C38: =+despacho!G33 | D38: =+despacho!I33 | E38: =IF(AND(B38<$M$24,B38>$M$25),1,0) | F38: =IF(AND(B38<$M$25,B38>0),1,0) | G38: =+despacho!J33 | H38: =+despacho!M33 | I38: =+despacho!K33 | J38: =+despacho!L33 | K38: Costo sacrificio: | M38: =+N38/$M$16 | N38: 58436 | O38: =+N38*M10 | Q38: R | R38: =+S38/$M$10 | S38: =+COUNTIF($J$7:$J$47,"R") | T38: Entre 45% - 49% | V38: =+C38-D38
A39: =+despacho!C34 | B39: =+IF((C39/$N$15)>0,(C39/$N$15)," ") | C39: =+despacho!G34 | D39: =+despacho!I34 | E39: =IF(AND(B39<$M$24,B39>$M$25),1,0) | F39: =IF(AND(B39<$M$25,B39>0),1,0) | G39: =+despacho!J34 | H39: =+despacho!M34 | I39: =+despacho!K34 | J39: =+despacho!L34 | K39: costo sacrif descartes | N39: 140792 | Q39: O | R39: =+S39/$M$10 | S39: =+COUNTIF($J$7:$J$47,"O") | T39: Entre 40% - 44% | V39: =+C39-D39
A40: =+despacho!C35 | B40: =+IF((C40/$N$15)>0,(C40/$N$15)," ") | C40: =+despacho!G35 | D40: =+despacho!I35 | E40: =IF(AND(B40<$M$24,B40>$M$25),1,0) | F40: =IF(AND(B40<$M$25,B40>0),1,0) | G40: =+despacho!J35 | H40: =+despacho!M35 | I40: =+despacho!K35 | J40: =+despacho!L35 | K40: Descuentos: | Q40: P | R40: =+S40/#REF! | S40: =+COUNTIF($J$7:$J$47,"P") | T40: Menos de 40% | V40: =+C40-D40
...

Sheet Consec
A3: FTA | B3: INFO | C3: PROVEEDOR | D3: GRANJA | E3: FECHA | H3: horas | K3: EXPENDIO | L3: # | M3: PESO | Q3: GRASA | R3: Magro | S3: LOMO | T3: RENDIMIENTOS | V3: Mermas | W3: % | X3: % | Y3: % | Z3: % | AA3: % | AB3: $/KG vivo | AE3: COSTO
B4: PORC | E4: LLEGADA | F4: SACRIFICIO | G4: DESPACHO | H4: desemb | I4: corr | J4: desp | M4: VIVO | N4: PROM | O4: CALIEN | P4: REFRIG | Q4: mm | R4: % | S4: MM | T4: C.Cal | U4: C,Rf | V4: % | W4: 80-90 KG | X4: - 80 KG | Y4: +17 mm | Z4: +22 mm | AA4: extra | AB4: BASE | AC4: PAGADO | AD4: PLANTA | AE4: LOTE | AF4: SACRIFIC | AG4: TOTAL
B6: =+lIQUIDACION!O3 | C6: =+lIQUIDACION!Q3 | D6: =+lIQUIDACION!Q4 | E6: =+lIQUIDACION!L4 | F6: =+lIQUIDACION!L6 | G6: =+lIQUIDACION!L7 | H6: =+lIQUIDACION!N5 | I6: =+lIQUIDACION!N6 | J6: =+lIQUIDACION!N8 | K6: =+lIQUIDACION!Q6 | L6: =+lIQUIDACION!M10 | M6: =+lIQUIDACION!L16 | N6: =+lIQUIDACION!M16 | O6: =+lIQUIDACION!N16 | P6: =+lIQUIDACION!O16 | Q6: =+lIQUIDACION!R16 | R6: =+lIQUIDACION!S16 | S6: =+lIQUIDACION!T16 | T6: =+lIQUIDACION!N17 | U6: =+lIQUIDACION!O17 | V6: =+lIQUIDACION!P16 | W6: =+lIQUIDACION!P24 | X6: =+lIQUIDACION!P25 | Y6: =+lIQUIDACION!P29+lIQUIDACION!P30 | Z6: =+lIQUIDACION!P31 | AA6: =+lIQUIDACION!P27 | AB6: =+lIQUIDACION!M35 | AC6: =+lIQUIDACION!M37 | AD6: =+lIQUIDACION!L3 | AE6: =+lIQUIDACION!O37 | AF6: =+lIQUIDACION!O38 | AG6: =+lIQUIDACION!O45

Sheet facturar
A1: CLIENTE EXPENDIO | B1: CLIENTE - RAZON SOCIAL | C1: NIT | D1: DIRECCION | E1: TELEFONO
A2: AP3 CARNES | B2: AP3 Carnes S.A | C2: 900,262,893-9 | D2: Cra 40 # 36 sur -30 | E2: 331 29 91
A3: AGROPORTO | B3: AGROINDISTRIA OPORTO SAS | C3: 900425237-8 | D3: CR 64 B 75 33 MEDELLIN | E3: 3221994
A4: CARNICOS BARILOCHE | B4: JULIAN RESTREPO MEDINA | C4: 71389252-8 | D4: CLLE 69 48 143 BRR CAMPO VALDEZ | E4: 6042120800
A5: CARNES COSTA AZUL | B5: Grupo Vaniglia S.A.S | C5: 900276439-9 | D5: Central Mayorista Bloque 19 Local 1C | E5: 285 63 48 Ext 3
A6: CARNES JP SAS | B6: CARNES JP SAS | C6: 901669364-6 | D6: CL 55 A 5736 | E6: 3116170958
A7: CARNES RIKA´S SAS | B7: CARNES RIKA´S SAS | C7: 901502831-7 | D7: cl 55 57 80 | E7: 3581519
A8: CARNES VITAL SAS | B8: CARNES VITAL SAS | C8: 900860359-2 | D8: CL 55 27 36 IN 186 SEC 8 LC 20 | E8: 5 1 1 9 3 7 4
A9: CARNES Y FILETES | B9: Comercializadora la Isabella SAS | D9: cr 29 a # 58 05 | E9: 2723253
A10: CENTRAL GANADERA | B10: CENTRAL GANADERA | C10: 811015602-1 | D10: calle103EE N0 63D 70 | E10: 2679272
A11: EL CORTESANO | B11: EL CORTESANO | C11: 900092749-6 | D11: clle 80sur 47c 24 | E11: 3010540
A12: FRIGOCARNES LTDA | B12: FrigoCarnes S.A.S | C12: 811030871-9 | D12: Cra 56 # 62-86 | E12: 511 99 77
A13: HERNANDO HIGUITA | B13: HERNANDO HIGUITA | C13: 71743607-7 | D13: cra 35 A # 39-16 | E13: 216 87 91
A14: INVERSIONES TORO ARISTIZABAL | B14: INVERSIONES TORO ARISTIZABAL S.A.S. | C14: 900379813-3 | D14: cl 80 sur 61 08 | E14: 6044441503
A15: INVERSIONES TRIBILIN | B15: inversiones tribilin sas | C15: 890942986-8 | D15: cl 27 41 189 | E15: 2773586
A16: ISRAEL MOLINA | B16: Carnes doble z | C16: 70112239 | D16: Plaza minorista local 4 y 5 | E16: 2510718
A17: LA CAMPIÑA | B17: Inversiones Posada Correa S.A.S | C17: 900736021-9 | D17: Calle 33 #76-67 | E17: 4132872
A18: CARNES LA GARANTIA PC SAS | B18: Carnes La Garantia PC S.A.S | C18: 900,349,322-0 | D18: Plaza Minorista local 56 | E18: 2 51 04 77
A19: LA HACIENDA | B19: inversiones de la hacienda sas | C19: 9011272245-2 | D19: calle 55 a57-36 lc 34-35-36 | E19: 3117206756
A20: CARNICERIA LOS ANGELES | B20: Inversiones Posada Correa S.A.S | C20: 900736021-9 | D20: Calle 33 #76-67 | E20: 4132872
A21: PACARDYL SUPERMERCADO -MAYORISTA | B21: Grupo Vaniglia S.A.S | C21: 900276439-9 | D21: Central Mayorista Bloque 19 Local 1C | E21: 285 63 48 Ext 3
A22: CARNES PIEMONTE | B22: PIEMONTE COMERCIALIZADORA DE CARNES | C22: 900607431-2 | D22: CLL 55 a 57-36 INT 188 | E22: 2516683
A23: RAPIPROVECARNES | B23: rapiprovecarnes s a s | C23: 900590169-0 | D23: kra 48 calle 85 192 | E23: 3545031
A24: SURTICARNES VALE | B24: surticarnes vale sas | C24: 900623167 | D24: cr 69 24 sur 20 brr villa claudia pd | E24: 3118122015
A25: URIEL GOMEZ | B25: Inversiones Uriel Gomez Acevedo SAS | C25: 900742425-5 | D25: Km1 Camilo C Amaga | E25: 4873577
A26: AGROPECUARIA NN | B26: AGROPECUARIA NN S.A.S. | C26: 901702660-2 | D26: CRA 23 11 57 CA 131 | E26: 3104622816
